Workbook

Sheet Summary
A1: Instance ID | B1: Routes (count) | C1: Deliveries (stops) | D1: Total distance (km, approx) | E1: Total energy consumption (kWh, VinFast VF8 est.) | F1: Total recharge energy after route (kWh, est.) | G1: Charging cost to replenish routes (VND) | H1: CO₂ reduction (kg CO₂) | J1: Traffic level | K1: Route count | L1: Source
A2: c101C10 | B2: =COUNTIF(Final_Dataset!$A:$A,A2) -> 7 | C2: =SUMIF(Final_Dataset!$A:$A,A2,Final_Dataset!$Q:$Q) -> 10 | D2: =ROUND(SUMIF(Final_Dataset!$A:$A,A2,Final_Dataset!$G:$G),2) -> 556.05 | E2: =ROUND(SUMIF(Final_Dataset!$A:$A,A2,Final_Dataset!$H:$H),2) -> 111.21 | F2: =ROUND(SUMIF(Final_Dataset!$A:$A,A2,Final_Dataset!$J:$J),2) -> 111.21 | G2: =ROUND(SUMIF(Final_Dataset!$A:$A,A2,Final_Dataset!$L:$L),0) -> 429050 | H2: =ROUND(SUMIF(Final_Dataset!$A:$A,A2,Final_Dataset!$R:$R),2) -> 138.19 | J2: Light | K2: 12 | L2: train.csv LOS-derived
A3: r102C10 | B3: =COUNTIF(Final_Dataset!$A:$A,A3) -> 5 | C3: =SUMIF(Final_Dataset!$A:$A,A3,Final_Dataset!$Q:$Q) -> 10 | D3: =ROUND(SUMIF(Final_Dataset!$A:$A,A3,Final_Dataset!$G:$G),2) -> 365.59 | E3: =ROUND(SUMIF(Final_Dataset!$A:$A,A3,Final_Dataset!$H:$H),2) -> 73.11 | F3: =ROUND(SUMIF(Final_Dataset!$A:$A,A3,Final_Dataset!$J:$J),2) -> 73.11 | G3: =ROUND(SUMIF(Final_Dataset!$A:$A,A3,Final_Dataset!$L:$L),0) -> 282059 | H3: =ROUND(SUMIF(Final_Dataset!$A:$A,A3,Final_Dataset!$R:$R),2) -> 90.86 | J3: Medium | K3: 5 | L3: train.csv LOS-derived
A4: rc102C10 | B4: =COUNTIF(Final_Dataset!$A:$A,A4) -> 6 | C4: =SUMIF(Final_Dataset!$A:$A,A4,Final_Dataset!$Q:$Q) -> 10 | D4: =ROUND(SUMIF(Final_Dataset!$A:$A,A4,Final_Dataset!$G:$G),2) -> 489.27 | E4: =ROUND(SUMIF(Final_Dataset!$A:$A,A4,Final_Dataset!$H:$H),2) -> 97.86 | F4: =ROUND(SUMIF(Final_Dataset!$A:$A,A4,Final_Dataset!$J:$J),2) -> 97.86 | G4: =ROUND(SUMIF(Final_Dataset!$A:$A,A4,Final_Dataset!$L:$L),0) -> 377544 | H4: =ROUND(SUMIF(Final_Dataset!$A:$A,A4,Final_Dataset!$R:$R),2) -> 121.62 | J4: Heavy | K4: 1 | L4: train.csv LOS-derived
A5: TOTAL | B5: =SUM(B2:B4) -> 18 | C5: =SUM(C2:C4) -> 30 | D5: =SUM(D2:D4) -> 1410.91 | E5: =SUM(E2:E4) -> 282.18 | F5: =SUM(F2:F4) -> 282.18 | G5: =SUM(G2:G4) -> 1088653 | H5: =SUM(H2:H4) -> 350.67
A7: Conversion note | B7: VinFast-based physical energy estimate
A8: Distance | B8: 1 Euclidean distance unit ≈ 1 km
A9: Energy | B9: VinFast VF 8 consumption = 20 kWh/100 km = 0.20 kWh/km
A10: Charging cost | B10: Recharge energy × 3,858 VND/kWh
A11: Time | B11: 1 benchmark time unit ≈ 1 minute; recharge time uses g min/kWh
A12: Reason | B12: Avoids the incorrect assumption 1 km = 1 kWh; uses the VinFast source as a real-world approximation.

Sheet Final_Dataset
A1: Instance ID | B1: Route ID | C1: Vehicle ID | D1: Start time (HH:MM) | E1: Start time offset (min, approx) | F1: Route sequence (node IDs) | G1: Total route distance (km, approx) | H1: Energy consumption (kWh, VinFast VF8 est.) | I1: SOC after route (%) | J1: Recharge energy after route (kWh, est.) | K1: Estimated recharge time after route (min) | L1: Charging cost to replenish route (VND) | M1: Traffic period (30-min) | N1: Traffic LOS (A-F) | O1: Traffic level (LOS-derived) | P1: Traffic mapping note | Q1: Delivery count (stops) | R1: CO₂ reduction (kg CO₂) | S1: Total demand (load unit) | T1: Time window status | U1: Notes
A2: c101C10 | B2: R_C101_01 | C2: EV_C101_01 | D2: 09:57 | E2: 177 | F2: D0 → C96 → C95 → S3 → D0 | G2: 79.68 | H2: =ROUND(G2*Assumptions!$B$4,2) -> 15.94 | I2: =ROUND(MAX(0,((IF($A2="r102C10",60.63,77.75))-H2)/(IF($A2="r102C10",60.63,77.75))*100),2) -> 79.5 | J2: =H2 -> 15.94 | K2: =ROUND(J2*(IF($A2="c101C10",3.47,IF($A2="r102C10",0.49,0.39))),2) -> 55.31 | L2: =ROUND(J2*Assumptions!$B$2,0) -> 61497 | M2: period_9_30 | N2: C | O2: Medium | P2: Matched route start time to train.csv period | Q2: 2 | R2: =ROUND(G2*Assumptions!$B$3,2) -> 19.8 | S2: 40 | T2: OK | U2: early clustered north customers
A3: c101C10 | B3: R_C101_02 | C3: EV_C101_02 | D3: 10:01 | E3: 181 | F3: D0 → C98 → D0 | G3: 61.61 | H3: =ROUND(G3*Assumptions!$B$4,2) -> 12.32 | I3: =ROUND(MAX(0,((IF($A3="r102C10",60.63,77.75))-H3)/(IF($A3="r102C10",60.63,77.75))*100),2) -> 84.15 | J3: =H3 -> 12.32 | K3: =ROUND(J3*(IF($A3="c101C10",3.47,IF($A3="r102C10",0.49,0.39))),2) -> 42.75 | L3: =ROUND(J3*Assumptions!$B$2,0) -> 47531 | M3: period_10_00 | N3: B | O3: Light | P3: Matched route start time to train.csv period | Q3: 1 | R3: =ROUND(G3*Assumptions!$B$3,2) -> 15.31 | S3: 20 | T3: OK | U3: single early north customer
A4: c101C10 | B4: R_C101_03 | C4: EV_C101_03 | D4: 11:23 | E4: 263 | F4: D0 → C27 → C4 → D0 | G4: 60.07 | H4: =ROUND(G4*Assumptions!$B$4,2) -> 12.01 | I4: =ROUND(MAX(0,((IF($A4="r102C10",60.63,77.75))-H4)/(IF($A4="r102C10",60.63,77.75))*100),2) -> 84.55 | J4: =H4 -> 12.01 | K4: =ROUND(J4*(IF($A4="c101C10",3.47,IF($A4="r102C10",0.49,0.39))),2) -> 41.67 | L4: =ROUND(J4*Assumptions!$B$2,0) -> 46335 | M4: period_11_00 | N4: C | O4: Medium | P4: Matched route start time to train.csv period | Q4: 2 | R4: =ROUND(G4*Assumptions!$B$3,2) -> 14.93 | S4: 20 | T4: OK | U4: west/north mid-window customers
A5: c101C10 | B5: R_C101_04 | C5: EV_C101_04 | D5: 18:07 | E5: 667 | F5: D0 → C78 → S20 → D0 | G5: 113.18 | H5: =ROUND(G5*Assumptions!$B$4,2) -> 22.64 | I5: =ROUND(MAX(0,((IF($A5="r102C10",60.63,77.75))-H5)/(IF($A5="r102C10",60.63,77.75))*100),2) -> 70.88 | J5: =H5 -> 22.64 | K5: =ROUND(J5*(IF($A5="c101C10",3.47,IF($A5="r102C10",0.49,0.39))),2) -> 78.56 | L5: =ROUND(J5*Assumptions!$B$2,0) -> 87345 | M5: period_18_00 | N5: D | O5: Medium | P5: Matched route start time to train.csv period | Q5: 1 | R5: =ROUND(G5*Assumptions!$B$3,2) -> 28.13 | S5: 20 | T5: OK | U5: east customer with recharge before return
A6: c101C10 | B6: R_C101_05 | C6: EV_C101_05 | D6: 19:24 | E6: 744 | F6: D0 → C100 → S3 → C89 → D0 | G6: 90.77 | H6: =ROUND(G6*Assumptions!$B$4,2) -> 18.15 | I6: =ROUND(MAX(0,((IF($A6="r102C10",60.63,77.75))-H6)/(IF($A6="r102C10",60.63,77.75))*100),2) -> 76.66 | J6: =H6 -> 18.15 | K6: =ROUND(J6*(IF($A6="c101C10",3.47,IF($A6="r102C10",0.49,0.39))),2) -> 62.98 | L6: =ROUND(J6*Assumptions!$B$2,0) -> 70023 | M6: period_19_00 | N6: C | O6: Medium | P6: Matched route start time to train.csv period | Q6: 2 | R6: =ROUND(G6*Assumptions!$B$3,2) -> 22.56 | S6: 30 | T6: OK | U6: north-east to central customer with recharge
A7: c101C10 | B7: R_C101_06 | C7: EV_C101_06 | D7: 20:30 | E7: 810 | F7: D0 → C54 → S16 → D0 | G7: 89.13 | H7: =ROUND(G7*Assumptions!$B$4,2) -> 17.83 | I7: =ROUND(MAX(0,((IF($A7="r102C10",60.63,77.75))-H7)/(IF($A7="r102C10",60.63,77.75))*100),2) -> 77.07 | J7: =H7 -> 17.83 | K7: =ROUND(J7*(IF($A7="c101C10",3.47,IF($A7="r102C10",0.49,0.39))),2) -> 61.87 | L7: =ROUND(J7*Assumptions!$B$2,0) -> 68788 | M7: period_20_00 | N7: F | O7: Heavy | P7: Matched route start time to train.csv period | Q7: 1 | R7: =ROUND(G7*Assumptions!$B$3,2) -> 22.15 | S7: 40 | T7: OK | U7: south customer with recharge before return
A8: c101C10 | B8: R_C101_07 | C8: EV_C101_07 | D8: 00:22+1d | E8: 1042 | F8: D0 → C13 → D0 | G8: 61.61 | H8: =ROUND(G8*Assumptions!$B$4,2) -> 12.32 | I8: =ROUND(MAX(0,((IF($A8="r102C10",60.63,77.75))-H8)/(IF($A8="r102C10",60.63,77.75))*100),2) -> 84.15 | J8: =H8 -> 12.32 | K8: =ROUND(J8*(IF($A8="c101C10",3.47,IF($A8="r102C10",0.49,0.39))),2) -> 42.75 | L8: =ROUND(J8*Assumptions!$B$2,0) -> 47531 | M8: period_0_00 | N8: D | O8: Medium | P8: Matched route start time to train.csv period | Q8: 1 | R8: =ROUND(G8*Assumptions!$B$3,2) -> 15.31 | S8: 30 | T8: OK | U8: late west/north customer
A9: r102C10 | B9: R_R102_01 | C9: EV_R102_01 | D9: 07:25 | E9: 25 | F9: D0 → C31 → C88 → D0 | G9: 41.7 | H9: =ROUND(G9*Assumptions!$B$4,2) -> 8.34 | I9: =ROUND(MAX(0,((IF($A9="r102C10",60.63,77.75))-H9)/(IF($A9="r102C10",60.63,77.75))*100),2) -> 86.24 | J9: =H9 -> 8.34 | K9: =ROUND(J9*(IF($A9="c101C10",3.47,IF($A9="r102C10",0.49,0.39))),2) -> 4.09 | L9: =ROUND(J9*Assumptions!$B$2,0) -> 32176 | M9: period_7_00 | N9: A | O9: Light | P9: Matched route start time to train.csv period | Q9: 2 | R9: =ROUND(G9*Assumptions!$B$3,2) -> 10.36 | S9: 36 | T9: OK | U9: north-west paired route
A10: r102C10 | B10: R_R102_02 | C10: EV_R102_02 | D10: 08:17 | E10: 77 | F10: D0 → C20 → S5 → C12 → D0 | G10: 98.71 | H10: =ROUND(G10*Assumptions!$B$4,2) -> 19.74 | I10: =ROUND(MAX(0,((IF($A10="r102C10",60.63,77.75))-H10)/(IF($A10="r102C10",60.63,77.75))*100),2) -> 67.44 | J10: =H10 -> 19.74 | K10: =ROUND(J10*(IF($A10="c101C10",3.47,IF($A10="r102C10",0.49,0.39))),2) -> 9.67 | L10: =ROUND(J10*Assumptions!$B$2,0) -> 76157 | M10: period_8_00 | N10: B | O10: Light | P10: Matched route start time to train.csv period | Q10: 2 | R10: =ROUND(G10*Assumptions!$B$3,2) -> 24.53 | S10: 28 | T10: OK | U10: north customer then central customer with recharge
A11: r102C10 | B11: R_R102_03 | C11: EV_R102_03 | D11: 08:37 | E11: 97 | F11: D0 → S17 → C23 → C67 → S18 → D0 | G11: 93.02 | H11: =ROUND(G11*Assumptions!$B$4,2) -> 18.6 | I11: =ROUND(MAX(0,((IF($A11="r102C10",60.63,77.75))-H11)/(IF($A11="r102C10",60.63,77.75))*100),2) -> 69.32 | J11: =H11 -> 18.6 | K11: =ROUND(J11*(IF($A11="c101C10",3.47,IF($A11="r102C10",0.49,0.39))),2) -> 9.11 | L11: =ROUND(J11*Assumptions!$B$2,0) -> 71759 | M11: period_8_30 | N11: B | O11: Light | P11: Matched route start time to train.csv period | Q11: 2 | R11: =ROUND(G11*Assumptions!$B$3,2) -> 23.12 | S11: 54 | T11: OK | U11: south-east pair with depot-to-station recharge
A12: r102C10 | B12: R_R102_04 | C12: EV_R102_04 | D12: 09:18 | E12: 138 | F12: D0 → C99 → C60 → D0 | G12: 44.06 | H12: =ROUND(G12*Assumptions!$B$4,2) -> 8.81 | I12: =ROUND(MAX(0,((IF($A12="r102C10",60.63,77.75))-H12)/(IF($A12="r102C10",60.63,77.75))*100),2) -> 85.47 | J12: =H12 -> 8.81 | K12: =ROUND(J12*(IF($A12="c101C10",3.47,IF($A12="r102C10",0.49,0.39))),2) -> 4.32 | L12: =ROUND(J12*Assumptions!$B$2,0) -> 33989 | M12: period_9_00 | N12: B | O12: Light | P12: Matched route start time to train.csv period | Q12: 2 | R12: =ROUND(G12*Assumptions!$B$3,2) -> 10.95 | S12: 12 | T12: OK | U12: west/south-west paired route
A13: r102C10 | B13: R_R102_05 | C13: EV_R102_05 | D13: 07:18 | E13: 18.03 | F13: D0 → C21 → S17 → C77 → D0 | G13: 88.1 | H13: =ROUND(G13*Assumptions!$B$4,2) -> 17.62 | I13: =ROUND(MAX(0,((IF($A13="r102C10",60.63,77.75))-H13)/(IF($A13="r102C10",60.63,77.75))*100),2) -> 70.94 | J13: =H13 -> 17.62 | K13: =ROUND(J13*(IF($A13="c101C10",3.47,IF($A13="r102C10",0.49,0.39))),2) -> 8.63 | L13: =ROUND(J13*Assumptions!$B$2,0) -> 67978 | M13: period_7_00 | N13: A | O13: Light | P13: Matched route start time to train.csv period | Q13: 2 | R13: =ROUND(G13*Assumptions!$B$3,2) -> 21.9 | S13: 25 | T13: OK | U13: south-to-east route with recharge
... A19: rc102C10 | B19: R_RC102_06 | C19: EV_RC102_06 | D19: 08:23 | E19: 83 | F19: D0 → C70 → D0 | G19: 39.29 | H19: =ROUND(G19*Assumptions!$B$4,2) -> 7.86 | I19: =ROUND(MAX(0,((IF($A19="r102C10",60.63,77.75))-H19)/(IF($A19="r102C10",60.63,77.75))*100),2) -> 89.89 | J19: =H19 -> 7.86 | K19: =ROUND(J19*(IF($A19="c101C10",3.47,IF($A19="r102C10",0.49,0.39))),2) -> 3.07 | L19: =ROUND(J19*Assumptions!$B$2,0) -> 30324 | M19: period_8_00 | N19: B | O19: Light | P19: Matched route start time to train.csv period | Q19: 1 | R19: =ROUND(G19*Assumptions!$B$3,2) -> 9.77 | S19: 23 | T19: OK | U19: north customer

Sheet Route_Steps
A1: Instance ID | B1: Route ID | C1: Vehicle ID | D1: Step No. | E1: From node | F1: To node | G1: From type | H1: To type | I1: Segment distance (km, approx) | J1: Energy used (kWh, VinFast VF8 est.) | K1: Battery before segment (kWh, approx) | L1: Battery after segment (kWh, approx) | M1: In-route charged at From node (kWh, est.) | N1: In-route charging time at From node (min, est.) | O1: Arrival time (min, approx) | P1: Wait time (min, approx) | Q1: Service start (min, approx) | R1: Service end (min, approx)
A2: c101C10 | B2: R_C101_01 | C2: EV_C101_01 | D2: 1 | E2: D0 | F2: C96 | G2: d | H2: c | I2: 36.06 | J2: =ROUND(I2*Assumptions!$B$4,2) -> 7.21 | K2: =ROUND(IF(D2=1,IF($A2="r102C10",60.63,77.75),L1),2) -> 77.75 | L2: =ROUND(K2-J2+M2,2) -> 70.54 | M2: 0 | N2: 0 | O2: 36.06 | P2: 140.94 | Q2: 177 | R2: 267
A3: c101C10 | B3: R_C101_01 | C3: EV_C101_01 | D3: 2 | E3: C96 | F3: C95 | G3: c | H3: c | I3: 2 | J3: =ROUND(I3*Assumptions!$B$4,2) -> 0.4 | K3: =ROUND(IF(D3=1,IF($A3="r102C10",60.63,77.75),L2),2) -> 70.54 | L3: =ROUND(K3-J3+M3,2) -> 70.14 | M3: 0 | N3: 0 | O3: 269 | P3: 5 | Q3: 274 | R3: 364
A4: c101C10 | B4: R_C101_01 | C4: EV_C101_01 | D4: 3 | E4: C95 | F4: S3 | G4: c | H4: f | I4: 5.39 | J4: =ROUND(I4*Assumptions!$B$4,2) -> 1.08 | K4: =ROUND(IF(D4=1,IF($A4="r102C10",60.63,77.75),L3),2) -> 70.14 | L4: =ROUND(K4-J4+M4,2) -> 69.06 | M4: 0 | N4: 0 | O4: 369.39 | P4: 0
A5: c101C10 | B5: R_C101_01 | C5: EV_C101_01 | D5: 4 | E5: S3 | F5: D0 | G5: f | H5: d | I5: 36.24 | J5: =ROUND(I5*Assumptions!$B$4,2) -> 7.25 | K5: =ROUND(IF(D5=1,IF($A5="r102C10",60.63,77.75),L4),2) -> 69.06 | L5: =ROUND(K5-J5+M5,2) -> 61.81 | M5: 0 | N5: 0 | O5: 412.3 | P5: 0
A6: c101C10 | B6: R_C101_02 | C6: EV_C101_02 | D6: 1 | E6: D0 | F6: C98 | G6: d | H6: c | I6: 30.81 | J6: =ROUND(I6*Assumptions!$B$4,2) -> 6.16 | K6: =ROUND(IF(D6=1,IF($A6="r102C10",60.63,77.75),L5),2) -> 77.75 | L6: =ROUND(K6-J6+M6,2) -> 71.59 | M6: 0 | N6: 0 | O6: 30.81 | P6: 150.19 | Q6: 181 | R6: 271
A7: c101C10 | B7: R_C101_02 | C7: EV_C101_02 | D7: 2 | E7: C98 | F7: D0 | G7: c | H7: d | I7: 30.81 | J7: =ROUND(I7*Assumptions!$B$4,2) -> 6.16 | K7: =ROUND(IF(D7=1,IF($A7="r102C10",60.63,77.75),L6),2) -> 71.59 | L7: =ROUND(K7-J7+M7,2) -> 65.43 | M7: 0 | N7: 0 | O7: 301.81 | P7: 0
A8: c101C10 | B8: R_C101_03 | C8: EV_C101_03 | D8: 1 | E8: D0 | F8: C27 | G8: d | H8: c | I8: 17.12 | J8: =ROUND(I8*Assumptions!$B$4,2) -> 3.42 | K8: =ROUND(IF(D8=1,IF($A8="r102C10",60.63,77.75),L7),2) -> 77.75 | L8: =ROUND(K8-J8+M8,2) -> 74.33 | M8: 0 | N8: 0 | O8: 17.12 | P8: 245.88 | Q8: 263 | R8: 353
A9: c101C10 | B9: R_C101_03 | C9: EV_C101_03 | D9: 2 | E9: C27 | F9: C4 | G9: c | H9: c | I9: 24.84 | J9: =ROUND(I9*Assumptions!$B$4,2) -> 4.97 | K9: =ROUND(IF(D9=1,IF($A9="r102C10",60.63,77.75),L8),2) -> 74.33 | L9: =ROUND(K9-J9+M9,2) -> 69.36 | M9: 0 | N9: 0 | O9: 377.84 | P9: 206.16 | Q9: 584 | R9: 674
A10: c101C10 | B10: R_C101_03 | C10: EV_C101_03 | D10: 3 | E10: C4 | F10: D0 | G10: c | H10: d | I10: 18.11 | J10: =ROUND(I10*Assumptions!$B$4,2) -> 3.62 | K10: =ROUND(IF(D10=1,IF($A10="r102C10",60.63,77.75),L9),2) -> 69.36 | L10: =ROUND(K10-J10+M10,2) -> 65.74 | M10: 0 | N10: 0 | O10: 692.11 | P10: 0
A11: c101C10 | B11: R_C101_04 | C11: EV_C101_04 | D11: 1 | E11: D0 | F11: C78 | G11: d | H11: c | I11: 50.29 | J11: =ROUND(I11*Assumptions!$B$4,2) -> 10.06 | K11: =ROUND(IF(D11=1,IF($A11="r102C10",60.63,77.75),L10),2) -> 77.75 | L11: =ROUND(K11-J11+M11,2) -> 67.69 | M11: 0 | N11: 0 | O11: 50.29 | P11: 616.71 | Q11: 667 | R11: 757
A12: c101C10 | B12: R_C101_04 | C12: EV_C101_04 | D12: 2 | E12: C78 | F12: S20 | G12: c | H12: f | I12: 9.43 | J12: =ROUND(I12*Assumptions!$B$4,2) -> 1.89 | K12: =ROUND(IF(D12=1,IF($A12="r102C10",60.63,77.75),L11),2) -> 67.69 | L12: =ROUND(K12-J12+M12,2) -> 65.8 | M12: 0 | N12: 0 | O12: 766.43 | P12: 0
A13: c101C10 | B13: R_C101_04 | C13: EV_C101_04 | D13: 3 | E13: S20 | F13: D0 | G13: f | H13: d | I13: 53.46 | J13: =ROUND(I13*Assumptions!$B$4,2) -> 10.69 | K13: =ROUND(IF(D13=1,IF($A13="r102C10",60.63,77.75),L12),2) -> 65.8 | L13: =ROUND(K13-J13+M13,2) -> 55.11 | M13: 0 | N13: 0 | O13: 942.85 | P13: 0
A14: c101C10 | B14: R_C101_05 | C14: EV_C101_05 | D14: 1 | E14: D0 | F14: C100 | G14: d | H14: c | I14: 38.08 | J14: =ROUND(I14*Assumptions!$B$4,2) -> 7.62 | K14: =ROUND(IF(D14=1,IF($A14="r102C10",60.63,77.75),L13),2) -> 77.75 | L14: =ROUND(K14-J14+M14,2) -> 70.13 | M14: 0 | N14: 0 | O14: 38.08 | P14: 705.92 | Q14: 744 | R14: 834
A15: c101C10 | B15: R_C101_05 | C15: EV_C101_05 | D15: 2 | E15: C100 | F15: S3 | G15: c | H15: f | I15: 3.61 | J15: =ROUND(I15*Assumptions!$B$4,2) -> 0.72 | K15: =ROUND(IF(D15=1,IF($A15="r102C10",60.63,77.75),L14),2) -> 70.13 | L15: =ROUND(K15-J15+M15,2) -> 69.41 | M15: 0 | N15: 0 | O15: 837.61 | P15: 0
A16: c101C10 | B16: R_C101_05 | C16: EV_C101_05 | D16: 3 | E16: S3 | F16: C89 | G16: f | H16: c | I16: 24.74 | J16: =ROUND(I16*Assumptions!$B$4,2) -> 4.95 | K16: =ROUND(IF(D16=1,IF($A16="r102C10",60.63,77.75),L15),2) -> 69.41 | L16: =ROUND(K16-J16+M16,2) -> 64.46 | M16: 0 | N16: 0 | O16: 907.54 | P16: 21.46 | Q16: 929 | R16: 1019
A17: c101C10 | B17: R_C101_05 | C17: EV_C101_05 | D17: 4 | E17: C89 | F17: D0 | G17: c | H17: d | I17: 24.35 | J17: =ROUND(I17*Assumptions!$B$4,2) -> 4.87 | K17: =ROUND(IF(D17=1,IF($A17="r102C10",60.63,77.75),L16),2) -> 64.46 | L17: =ROUND(K17-J17+M17,2) -> 59.59 | M17: 0 | N17: 0 | O17: 1043.35 | P17: 0
A18: c101C10 | B18: R_C101_06 | C18: EV_C101_06 | D18: 1 | E18: D0 | F18: C54 | G18: d | H18: c | I18: 40.05 | J18: =ROUND(I18*Assumptions!$B$4,2) -> 8.01 | K18: =ROUND(IF(D18=1,IF($A18="r102C10",60.63,77.75),L17),2) -> 77.75 | L18: =ROUND(K18-J18+M18,2) -> 69.74 | M18: 0 | N18: 0 | O18: 40.05 | P18: 769.95 | Q18: 810 | R18: 900
A19: c101C10 | B19: R_C101_06 | C19: EV_C101_06 | D19: 2 | E19: C54 | F19: S16 | G19: c | H19: f | I19: 6.32 | J19: =ROUND(I19*Assumptions!$B$4,2) -> 1.26 | K19: =ROUND(IF(D19=1,IF($A19="r102C10",60.63,77.75),L18),2) -> 69.74 | L19: =ROUND(K19-J19+M19,2) -> 68.48 | M19: 0 | N19: 0 | O19: 906.32 | P19: 0
A20: c101C10 | B20: R_C101_06 | C20: EV_C101_06 | D20: 3 | E20: S16 | F20: D0 | G20: f | H20: d | I20: 42.76 | J20: =ROUND(I20*Assumptions!$B$4,2) -> 8.55 | K20: =ROUND(IF(D20=1,IF($A20="r102C10",60.63,77.75),L19),2) -> 68.48 | L20: =ROUND(K20-J20+M20,2) -> 59.93 | M20: 0 | N20: 0 | O20: 988.57 | P20: 0
A21: c101C10 | B21: R_C101_07 | C21: EV_C101_07 | D21: 1 | E21: D0 | F21: C13 | G21: d | H21: c | I21: 30.81 | J21: =ROUND(I21*Assumptions!$B$4,2) -> 6.16 | K21: =ROUND(IF(D21=1,IF($A21="r102C10",60.63,77.75),L20),2) -> 77.75 | L21: =ROUND(K21-J21+M21,2) -> 71.59 | M21: 0 | N21: 0 | O21: 30.81 | P21: 1011.19 | Q21: 1042 | R21: 1132
A22: c101C10 | B22: R_C101_07 | C22: EV_C101_07 | D22: 2 | E22: C13 | F22: D0 | G22: c | H22: d | I22: 30.81 | J22: =ROUND(I22*Assumptions!$B$4,2) -> 6.16 | K22: =ROUND(IF(D22=1,IF($A22="r102C10",60.63,77.75),L21),2) -> 71.59 | L22: =ROUND(K22-J22+M22,2) -> 65.43 | M22: 0 | N22: 0 | O22: 1162.81 | P22: 0
A23: r102C10 | B23: R_R102_01 | C23: EV_R102_01 | D23: 1 | E23: D0 | F23: C31 | G23: d | H23: c | I23: 17.46 | J23: =ROUND(I23*Assumptions!$B$4,2) -> 3.49 | K23: =ROUND(IF(D23=1,IF($A23="r102C10",60.63,77.75),L22),2) -> 60.63 | L23: =ROUND(K23-J23+M23,2) -> 57.14 | M23: 0 | N23: 0 | O23: 17.46 | P23: 7.54 | Q23: 25 | R23: 35
A24: r102C10 | B24: R_R102_01 | C24: EV_R102_01 | D24: 2 | E24: C31 | F24: C88 | G24: c | H24: c | I24: 5 | J24: =ROUND(I24*Assumptions!$B$4,2) -> 1 | K24: =ROUND(IF(D24=1,IF($A24="r102C10",60.63,77.75),L23),2) -> 57.14 | L24: =ROUND(K24-J24+M24,2) -> 56.14 | M24: 0 | N24: 0 | O24: 40 | P24: 126 | Q24: 166 | R24: 176
A25: r102C10 | B25: R_R102_01 | C25: EV_R102_01 | D25: 3 | E25: C88 | F25: D0 | G25: c | H25: d | I25: 19.24 | J25: =ROUND(I25*Assumptions!$B$4,2) -> 3.85 | K25: =ROUND(IF(D25=1,IF($A25="r102C10",60.63,77.75),L24),2) -> 56.14 | L25: =ROUND(K25-J25+M25,2) -> 52.29 | M25: 0 | N25: 0 | O25: 195.24 | P25: 0
A26: r102C10 | B26: R_R102_02 | C26: EV_R102_02 | D26: 1 | E26: D0 | F26: C20 | G26: d | H26: c | I26: 31.62 | J26: =ROUND(I26*Assumptions!$B$4,2) -> 6.32 | K26: =ROUND(IF(D26=1,IF($A26="r102C10",60.63,77.75),L25),2) -> 60.63 | L26: =ROUND(K26-J26+M26,2) -> 54.31 | M26: 0 | N26: 0 | O26: 31.62 | P26: 45.38 | Q26: 77 | R26: 87
A27: r102C10 | B27: R_R102_02 | C27: EV_R102_02 | D27: 2 | E27: C20 | F27: S5 | G27: c | H27: f | I27: 17.26 | J27: =ROUND(I27*Assumptions!$B$4,2) -> 3.45 | K27: =ROUND(IF(D27=1,IF($A27="r102C10",60.63,77.75),L26),2) -> 54.31 | L27: =ROUND(K27-J27+M27,2) -> 50.86 | M27: 0 | N27: 0 | O27: 104.26 | P27: 0
A28: r102C10 | B28: R_R102_02 | C28: EV_R102_02 | D28: 3 | E28: S5 | F28: C12 | G28: f | H28: c | I28: 34.83 | J28: =ROUND(I28*Assumptions!$B$4,2) -> 6.97 | K28: =ROUND(IF(D28=1,IF($A28="r102C10",60.63,77.75),L27),2) -> 50.86 | L28: =ROUND(K28-J28+M28,2) -> 43.89 | M28: 0 | N28: 0 | O28: 157.75 | P28: 19.25 | Q28: 177 | R28: 187
A29: r102C10 | B29: R_R102_02 | C29: EV_R102_02 | D29: 4 | E29: C12 | F29: D0 | G29: c | H29: d | I29: 15 | J29: =ROUND(I29*Assumptions!$B$4,2) -> 3 | K29: =ROUND(IF(D29=1,IF($A29="r102C10",60.63,77.75),L28),2) -> 43.89 | L29: =ROUND(K29-J29+M29,2) -> 40.89 | M29: 0 | N29: 0 | O29: 202 | P29: 0
A30: r102C10 | B30: R_R102_03 | C30: EV_R102_03 | D30: 1 | E30: D0 | F30: S17 | G30: d | H30: f | I30: 32.25 | J30: =ROUND(I30*Assumptions!$B$4,2) -> 6.45 | K30: =ROUND(IF(D30=1,IF($A30="r102C10",60.63,77.75),L29),2) -> 60.63 | L30: =ROUND(K30-J30+M30,2) -> 54.18 | M30: 0 | N30: 0 | O30: 32.25 | P30: 0
A31: r102C10 | B31: R_R102_03 | C31: EV_R102_03 | D31: 2 | E31: S17 | F31: C23 | G31: f | H31: c | I31: 4.47 | J31: =ROUND(I31*Assumptions!$B$4,2) -> 0.89 | K31: =ROUND(IF(D31=1,IF($A31="r102C10",60.63,77.75),L30),2) -> 54.18 | L31: =ROUND(K31-J31+M31,2) -> 53.29 | M31: 0 | N31: 0 | O31: 36.72 | P31: 60.28 | Q31: 97 | R31: 107
A32: r102C10 | B32: R_R102_03 | C32: EV_R102_03 | D32: 3 | E32: C23 | F32: C67 | G32: c | H32: c | I32: 12 | J32: =ROUND(I32*Assumptions!$B$4,2) -> 2.4 | K32: =ROUND(IF(D32=1,IF($A32="r102C10",60.63,77.75),L31),2) -> 53.29 | L32: =ROUND(K32-J32+M32,2) -> 50.89 | M32: 0 | N32: 0 | O32: 119 | P32: 0 | Q32: 119 | R32: 129
A33: r102C10 | B33: R_R102_03 | C33: EV_R102_03 | D33: 4 | E33: C67 | F33: S18 | G33: c | H33: f | I33: 8.06 | J33: =ROUND(I33*Assumptions!$B$4,2) -> 1.61 | K33: =ROUND(IF(D33=1,IF($A33="r102C10",60.63,77.75),L32),2) -> 50.89 | L33: =ROUND(K33-J33+M33,2) -> 49.28 | M33: 0 | N33: 0 | O33: 137.06 | P33: 0
A34: r102C10 | B34: R_R102_03 | C34: EV_R102_03 | D34: 5 | E34: S18 | F34: D0 | G34: f | H34: d | I34: 36.24 | J34: =ROUND(I34*Assumptions!$B$4,2) -> 7.25 | K34: =ROUND(IF(D34=1,IF($A34="r102C10",60.63,77.75),L33),2) -> 49.28 | L34: =ROUND(K34-J34+M34,2) -> 42.03 | M34: 0 | N34: 0 | O34: 189.17 | P34: 0
A35: r102C10 | B35: R_R102_04 | C35: EV_R102_04 | D35: 1 | E35: D0 | F35: C99 | G35: d | H35: c | I35: 17.49 | J35: =ROUND(I35*Assumptions!$B$4,2) -> 3.5 | K35: =ROUND(IF(D35=1,IF($A35="r102C10",60.63,77.75),L34),2) -> 60.63 | L35: =ROUND(K35-J35+M35,2) -> 57.13 | M35: 0 | N35: 0 | O35: 17.49 | P35: 120.51 | Q35: 138 | R35: 148
A36: r102C10 | B36: R_R102_04 | C36: EV_R102_04 | D36: 2 | E36: C99 | F36: C60 | G36: c | H36: c | I36: 8.54 | J36: =ROUND(I36*Assumptions!$B$4,2) -> 1.71 | K36: =ROUND(IF(D36=1,IF($A36="r102C10",60.63,77.75),L35),2) -> 57.13 | L36: =ROUND(K36-J36+M36,2) -> 55.42 | M36: 0 | N36: 0 | O36: 156.54 | P36: 0 | Q36: 156.54 | R36: 166.54
A37: r102C10 | B37: R_R102_04 | C37: EV_R102_04 | D37: 3 | E37: C60 | F37: D0 | G37: c | H37: d | I37: 18.03 | J37: =ROUND(I37*Assumptions!$B$4,2) -> 3.61 | K37: =ROUND(IF(D37=1,IF($A37="r102C10",60.63,77.75),L36),2) -> 55.42 | L37: =ROUND(K37-J37+M37,2) -> 51.81 | M37: 0 | N37: 0 | O37: 184.57 | P37: 0
A38: r102C10 | B38: R_R102_05 | C38: EV_R102_05 | D38: 1 | E38: D0 | F38: C21 | G38: d | H38: c | I38: 18.03 | J38: =ROUND(I38*Assumptions!$B$4,2) -> 3.61 | K38: =ROUND(IF(D38=1,IF($A38="r102C10",60.63,77.75),L37),2) -> 60.63 | L38: =ROUND(K38-J38+M38,2) -> 57.02 | M38: 0 | N38: 0 | O38: 18.03 | P38: 0 | Q38: 18.03 | R38: 28.03
A39: r102C10 | B39: R_R102_05 | C39: EV_R102_05 | D39: 2 | E39: C21 | F39: S17 | G39: c | H39: f | I39: 14.32 | J39: =ROUND(I39*Assumptions!$B$4,2) -> 2.86 | K39: =ROUND(IF(D39=1,IF($A39="r102C10",60.63,77.75),L38),2) -> 57.02 | L39: =ROUND(K39-J39+M39,2) -> 54.16 | M39: 0 | N39: 0 | O39: 42.35 | P39: 0
A40: r102C10 | B40: R_R102_05 | C40: EV_R102_05 | D40: 3 | E40: S17 | F40: C77 | G40: f | H40: c | I40: 36.06 | J40: =ROUND(I40*Assumptions!$B$4,2) -> 7.21 | K40: =ROUND(IF(D40=1,IF($A40="r102C10",60.63,77.75),L39),2) -> 54.16 | L40: =ROUND(K40-J40+M40,2) -> 46.95 | M40: 0 | N40: 0 | O40: 91.86 | P40: 58.14 | Q40: 150 | R40: 160
...

Sheet Raw_Nodes
A1: Instance ID | B1: StringID / Node ID | C1: Type (d/f/c) | D1: x coordinate (km-scale approx) | E1: y coordinate (km-scale approx) | F1: Demand (load unit) | G1: ReadyTime (min, approx) | H1: DueDate (min, approx) | I1: ServiceTime (min, approx) | J1: Q battery capacity (kWh, approx) | K1: C vehicle load capacity (load unit) | L1: r consumption rate (kWh/km, approx) | M1: g inverse refueling rate (min/kWh, approx) | N1: v average velocity (km/min, approx)
A2: c101C10 | B2: D0 | C2: d | D2: 40 | E2: 50 | F2: 0 | G2: 0 | H2: 1236 | I2: 0 | J2: 77.75 | K2: 200 | L2: 1 | M2: 3.47 | N2: 1
A3: c101C10 | B3: S0 | C3: f | D3: 40 | E3: 50 | F3: 0 | G3: 0 | H3: 1236 | I3: 0 | J3: 77.75 | K3: 200 | L3: 1 | M3: 3.47 | N3: 1
A4: c101C10 | B4: S1 | C4: f | D4: 77 | E4: 52 | F4: 0 | G4: 0 | H4: 1236 | I4: 0 | J4: 77.75 | K4: 200 | L4: 1 | M4: 3.47 | N4: 1
A5: c101C10 | B5: S16 | C5: f | D5: 48 | E5: 8 | F5: 0 | G5: 0 | H5: 1236 | I5: 0 | J5: 77.75 | K5: 200 | L5: 1 | M5: 3.47 | N5: 1
A6: c101C10 | B6: S20 | C6: f | D6: 93 | E6: 43 | F6: 0 | G6: 0 | H6: 1236 | I6: 0 | J6: 77.75 | K6: 200 | L6: 1 | M6: 3.47 | N6: 1
A7: c101C10 | B7: S3 | C7: f | D7: 57 | E7: 82 | F7: 0 | G7: 0 | H7: 1236 | I7: 0 | J7: 77.75 | K7: 200 | L7: 1 | M7: 3.47 | N7: 1
A8: c101C10 | B8: C100 | C8: c | D8: 55 | E8: 85 | F8: 20 | G8: 744 | H8: 798 | I8: 90 | J8: 77.75 | K8: 200 | L8: 1 | M8: 3.47 | N8: 1
A9: c101C10 | B9: C13 | C9: c | D9: 22 | E9: 75 | F9: 30 | G9: 1042 | H9: 1106 | I9: 90 | J9: 77.75 | K9: 200 | L9: 1 | M9: 3.47 | N9: 1
A10: c101C10 | B10: C27 | C10: c | D10: 23 | E10: 52 | F10: 10 | G10: 263 | H10: 311 | I10: 90 | J10: 77.75 | K10: 200 | L10: 1 | M10: 3.47 | N10: 1
A11: c101C10 | B11: C4 | C11: c | D11: 42 | E11: 68 | F11: 10 | G11: 584 | H11: 656 | I11: 90 | J11: 77.75 | K11: 200 | L11: 1 | M11: 3.47 | N11: 1
A12: c101C10 | B12: C54 | C12: c | D12: 42 | E12: 10 | F12: 40 | G12: 810 | H12: 868 | I12: 90 | J12: 77.75 | K12: 200 | L12: 1 | M12: 3.47 | N12: 1
A13: c101C10 | B13: C78 | C13: c | D13: 88 | E13: 35 | F13: 20 | G13: 667 | H13: 731 | I13: 90 | J13: 77.75 | K13: 200 | L13: 1 | M13: 3.47 | N13: 1
... A47: rc102C10 | B47: C92 | C47: c | D47: 53 | E47: 43 | F47: 14 | G47: 140 | H47: 170 | I47: 10 | J47: 77.75 | K47: 200 | L47: 1 | M47: 0.39 | N47: 1

Sheet Traffic_Source
A1: Traffic period (30-min) | B1: Time range | C1: Record count | D1: Total segment length (source unit) | E1: Length-weighted LOS score | F1: Representative LOS | G1: Traffic level | H1: LOS A count | I1: LOS B count | J1: LOS C count | K1: LOS D count | L1: LOS E count | M1: LOS F count | N1: Source note
A2: period_0_00 | B2: 00:00-00:30 | C2: 4383 | D2: 170103 | E2: 3.591 | F2: D | G2: Medium | H2: 344 | I2: 104 | J2: 893 | K2: 1736 | L2: 1125 | M2: 181 | N2: Length-weighted by segment length in train.csv
A3: period_0_30 | B3: 00:30-01:00 | C3: 1007 | D3: 56146 | E3: 2.982 | F3: C | G3: Medium | H3: 264 | I3: 118 | J3: 131 | K3: 111 | L3: 121 | M3: 262 | N3: Length-weighted by segment length in train.csv
A4: period_1_00 | B4: 01:00-01:30 | C4: 686 | D4: 32545 | E4: 3.47 | F4: C | G4: Medium | H4: 129 | I4: 80 | J4: 102 | K4: 98 | L4: 77 | M4: 200 | N4: Length-weighted by segment length in train.csv
A5: period_1_30 | B5: 01:30-02:00 | C5: 896 | D5: 46754 | E5: 3.463 | F5: C | G5: Medium | H5: 158 | I5: 86 | J5: 157 | K5: 147 | L5: 147 | M5: 201 | N5: Length-weighted by segment length in train.csv
A6: period_2_00 | B6: 02:00-02:30 | C6: 743 | D6: 32297 | E6: 3.253 | F6: C | G6: Medium | H6: 237 | I6: 51 | J6: 98 | K6: 99 | L6: 101 | M6: 157 | N6: Length-weighted by segment length in train.csv
A7: period_2_30 | B7: 02:30-03:00 | C7: 194 | D7: 8721 | E7: 2.308 | F7: B | G7: Light | H7: 134 | I7: 3 | J7: 4 | K7: 3 | L7: 7 | M7: 43 | N7: Length-weighted by segment length in train.csv
A8: period_3_00 | B8: 03:00-03:30 | C8: 559 | D8: 24620 | E8: 2.776 | F8: C | G8: Medium | H8: 201 | I8: 139 | J8: 43 | K8: 33 | L8: 40 | M8: 103 | N8: Length-weighted by segment length in train.csv
A9: period_3_30 | B9: 03:30-04:00 | C9: 989 | D9: 51035 | E9: 2.155 | F9: B | G9: Light | H9: 578 | I9: 96 | J9: 81 | K9: 50 | L9: 60 | M9: 124 | N9: Length-weighted by segment length in train.csv
A10: period_4_00 | B10: 04:00-04:30 | C10: 824 | D10: 44840 | E10: 1.877 | F10: B | G10: Light | H10: 546 | I10: 64 | J10: 47 | K10: 30 | L10: 30 | M10: 107 | N10: Length-weighted by segment length in train.csv
A11: period_4_30 | B11: 04:30-05:00 | C11: 1004 | D11: 51632 | E11: 2.092 | F11: B | G11: Light | H11: 528 | I11: 180 | J11: 70 | K11: 47 | L11: 42 | M11: 137 | N11: Length-weighted by segment length in train.csv
A12: period_5_00 | B12: 05:00-05:30 | C12: 769 | D12: 38211 | E12: 2.001 | F12: B | G12: Light | H12: 404 | I12: 197 | J12: 32 | K12: 29 | L12: 32 | M12: 75 | N12: Length-weighted by segment length in train.csv
A13: period_5_30 | B13: 05:30-06:00 | C13: 535 | D13: 26201 | E13: 1.824 | F13: B | G13: Light | H13: 311 | I13: 147 | J13: 24 | K13: 12 | L13: 6 | M13: 35 | N13: Length-weighted by segment length in train.csv
... A42: period_20_00 | B42: 20:00-20:30 | C42: 2 | D42: 262 | E42: 6 | F42: F | G42: Heavy | H42: 0 | I42: 0 | J42: 0 | K42: 0 | L42: 0 | M42: 2 | N42: Length-weighted by segment length in train.csv
A43: period_20_30 | B43: 20:30-21:00 | C43: 0 | D43: 0 | F43: No data | G43: No data | H43: 0 | I43: 0 | J43: 0 | K43: 0 | L43: 0 | M43: 0 | N43: No traffic records for this period
A44: period_21_00 | B44: 21:00-21:30 | C44: 0 | D44: 0 | F44: No data | G44: No data | H44: 0 | I44: 0 | J44: 0 | K44: 0 | L44: 0 | M44: 0 | N44: No traffic records for this period
A45: period_21_30 | B45: 21:30-22:00 | C45: 1 | D45: 68 | E45: 6 | F45: F | G45: Heavy | H45: 0 | I45: 0 | J45: 0 | K45: 0 | L45: 0 | M45: 1 | N45: Length-weighted by segment length in train.csv
A46: period_22_00 | B46: 22:00-22:30 | C46: 47 | D46: 10619 | E46: 1.582 | F46: B | G46: Light | H46: 34 | I46: 1 | J46: 3 | K46: 0 | L46: 1 | M46: 8 | N46: Length-weighted by segment length in train.csv
A47: period_22_30 | B47: 22:30-23:00 | C47: 61 | D47: 3379 | E47: 2.542 | F47: C | G47: Medium | H47: 31 | I47: 3 | J47: 1 | K47: 1 | L47: 0 | M47: 25 | N47: Length-weighted by segment length in train.csv
A48: period_23_00 | B48: 23:00-23:30 | C48: 178 | D48: 7106 | E48: 1.564 | F48: B | G48: Light | H48: 143 | I48: 3 | J48: 4 | K48: 6 | L48: 6 | M48: 16 | N48: Length-weighted by segment length in train.csv
A49: period_23_30 | B49: 23:30-00:00 | C49: 3996 | D49: 153967 | E49: 3.611 | F49: D | G49: Medium | H49: 446 | I49: 232 | J49: 1101 | K49: 483 | L49: 1205 | M49: 529 | N49: Length-weighted by segment length in train.csv

Sheet Unit_Conversion
A1: Original / source value | B1: Converted / used value | C1: Conversion factor | D1: Where used | E1: Reason / note
A2: Euclidean distance unit | B2: km | C2: 1 benchmark unit ≈ 1 km | D2: Total route distance, segment distance, CO₂ reduction | E2: Approximation only; original EVRPTW coordinates are not GPS measurements.
A3: VinFast VF 3 source rate | B3: 0.0833 kWh/km | C3: 83.3 kWh / 1,000 km | D3: Reference only | E3: Small car consumption from the VinFast source.
A4: VinFast VF 5 source rate | B4: 0.1400 kWh/km | C4: 140 kWh / 1,000 km | D4: Reference only | E4: Mid-size car consumption from the VinFast source.
A5: VinFast VF 8 selected rate | B5: 0.2000 kWh/km | C5: 200 kWh / 1,000 km | D5: Final_Dataset energy consumption | E5: Selected as the proxy for the EV delivery vehicle because benchmark battery capacities are around 60–78 kWh.
A6: Public charging price | B6: 3,858 VND/kWh | C6: as reported by VinFast source | D6: Charging cost | E6: Cost = recharge energy × 3,858.
A7: Benchmark time unit | B7: minute | C7: 1 unit ≈ 1 min | D7: ReadyTime, DueDate, ServiceTime, arrival/wait/service times | E7: Solomon/EVRPTW-style time units are interpreted as minutes for reporting.
A8: g inverse refueling rate | B8: min/kWh | C8: same numeric value from each instance | D8: Recharge time estimate | E8: Recharge time = recharge energy × g.
A9: Q battery capacity | B9: kWh | C9: same numeric value from each instance | D9: SOC calculation | E9: Q values such as 60.63 and 77.75 are interpreted as approximate kWh.
A10: r benchmark consumption parameter | B10: not used as real kWh/km | C10: Original r = 1.0 remains a benchmark parameter | D10: Raw_Nodes only | E10: Physical energy is recalculated using VinFast 0.20 kWh/km instead of r=1.0.
A11: LOS A-F | B11: Light/Medium/Heavy | C11: A/B=Light; C/D=Medium; E/F=Heavy | D11: Traffic level | E11: Simplified traffic category from Kaggle train.csv.

Sheet VinFast_Source_Rates
A1: Vehicle model | B1: Source energy for 1,000 km (kWh) | C1: Consumption rate (kWh/km) | D1: Public charging price (VND/kWh) | E1: Estimated charging cost for 1,000 km (VND) | F1: Source
A2: VinFast VF 3 | B2: 83.3 | C2: 0.0833 | D2: 3858 | E2: 321000 | F2: https://xedienvinfastdanang.com/di-xe-dien-vinfast-1-000km-ton-bao-nhieu-tien-dien-so-voi-xe-xang/
A3: VinFast VF 5 | B3: 140 | C3: 0.14 | D3: 3858 | E3: 540000 | F3: https://xedienvinfastdanang.com/di-xe-dien-vinfast-1-000km-ton-bao-nhieu-tien-dien-so-voi-xe-xang/
A4: VinFast VF 8 | B4: 200 | C4: 0.2 | D4: 3858 | E4: 772000 | F4: https://xedienvinfastdanang.com/di-xe-dien-vinfast-1-000km-ton-bao-nhieu-tien-dien-so-voi-xe-xang/
A5: Selected for this dataset | B5: VinFast VF 8 | C5: 0.2 | D5: 3858 | E5: Used for all route-level energy and charging cost recalculations | F5: Because Q≈60–78 kWh matches car/van-scale batteries better than small EVs

Sheet Assumptions
A1: Item | B1: Value | C1: Unit / Explanation | D1: Source / Note
A2: VinFast public charging price | B2: 3858 | C2: VND/kWh; public V-Green/VinFast charging station price; VAT included | D2: https://xedienvinfastdanang.com/di-xe-dien-vinfast-1-000km-ton-bao-nhieu-tien-dien-so-voi-xe-xang/
A3: ICE tailpipe emission factor | B3: 0.248548 | C3: kg CO₂/km; converted from EPA 400 g CO₂/mile | D3: https://www.epa.gov/greenvehicles/greenhouse-gas-emissions-typical-passenger-vehicle
A4: Selected VinFast energy consumption rate | B4: 0.2 | C4: kWh/km; based on VinFast VF 8 = 20 kWh/100 km = 200 kWh/1,000 km | D4: https://xedienvinfastdanang.com/di-xe-dien-vinfast-1-000km-ton-bao-nhieu-tien-dien-so-voi-xe-xang/
A5: Selected vehicle profile | B5: VinFast VF 8 / electric delivery van proxy | C5: Chosen because the benchmark battery capacities Q≈60–78 kWh are closer to car/van batteries than to small e-motorbike batteries | D5: Use this profile for Final_Dataset calculations
A6: Node x-y coordinate source | B6: c101C10.txt; r102C10.txt; rc102C10.txt | C6: x and y are original EVRPTW benchmark coordinates used as approximate locations for depot, customers, and charging stations. | D6: Extracted into Raw_Nodes from the uploaded EVRPTW instance files; these are benchmark coordinates, not GPS latitude/longitude.
A7: Distance conversion | B7: Approximate :1 EVRPTW Euclidean distance unit ≈ 1 km | C7: Distances are calculated from x-y coordinates using Euclidean distance, then reported as approximate km. | D7: c101C10.txt, r102C10.txt, and rc102C10.txt from the whole dataset from https://data.mendeley.com/datasets/h3mrm5dhxw/1
A8: Energy calculation | B8: Energy kWh = route distance km × 0.20 | C8: Do NOT use 1 km = 1 kWh. Original EVRPTW r=1.0 is treated as a benchmark parameter, not a real-world kWh/km value. | D8: Recalculated from VinFast source consumption rate
A9: Time conversion | B9: 1 benchmark time unit ≈ 1 minute | C9: ReadyTime, DueDate, ServiceTime, charging time, arrival time, wait time, service start/end are reported as approximate minutes. | D9: Common interpretation of Solomon/EVRPTW benchmark time units; suitable for approximation
A10: Recharge energy definition | B10: Recharge energy after route = energy consumed by route | C10: Charging cost estimates how much it costs to replenish the route's consumed energy after completing the route. | D10: This is not necessarily in-route charging at a station
A11: Charging rate conversion | B11: g = min/kWh | C11: Estimated recharge time = recharge energy × instance g. | D11: Route-specific g is taken from each instance file
A12: Battery / SOC | B12: Q and % | C12: Q = battery capacity in kWh after conversion; SOC = battery after route / Q × 100. | D12: Q is taken from each instance file
A13: Traffic data | B13: Kaggle HCM train.csv LOS by 30-minute period | C13: Traffic period is matched from route start time. LOS is aggregated by period using segment length; A/B=Light, C/D=Medium, E/F=Heavy. If a period has no records, nearest available period is used. | D13: Uploaded train.csv; source tables provided: segment_status.csv, segments.csv, nodes.csv, streets.csv
A14: CO₂ reduction | B14: Tailpipe avoided | C14: CO₂ reduction = total route distance in km × 0.248548. | D14: Use as estimated CO₂ reduction, not measured emissions
A15: Route construction | B15: Heuristic | C15: Routes were manually/heuristically constructed from the uploaded instances to generate a complete route-level dataset. | D15: Not solver-optimal routes
A16: Conversion limitation | B16: Approximate, not measured | C16: The conversion makes the dataset easier to interpret; it does not turn benchmark coordinates into field GPS measurements. | D16: Use wording “approximate” in report tables
